Workbook
Name Calibration_Date: [1]Calibration!$L$10
Name Calibration_Technician: [1]Calibration!$H$10
Name Circ_Fractions_Table: '[2]Fraction of Diameter'!$A$10:$G$21
Name Circ_Stack?: '[3]Title Page'!$D$20
Name Circ_Stack_Diam: '[3]Method 1 - Circular'!$E$16
Name Console_Model_Num: [1]Calibration!$D$4
Name Console_Serial_Num: [1]Calibration!$H$4
Name High_Flow_Orifice_Model: [1]Calibration!$H$7
Name Low_Flow_Orifice_Model: [1]Calibration!$L$7
Name M5R1_Dna: '[3]Method 5 - Run 1'!$M$16
Name Manufacture_Date: [1]Calibration!$L$4
Name Rect_Equiv_Diam: '[3]Method 1 - Rectangular'!$E$18
Name Rect_Stack?: '[3]Title Page'!$D$21
Name Totalizer_Model: [1]Calibration!$D$6
Name Totalizer_Scale_Factor: [1]Calibration!$H$6
Name ubiog: '[4]U. Biogeografica'!$E$2:$E$18
Name Yavg: [1]Calibration!$K$44

Sheet FOM303-32-Imprimir
C1: K2 INGENIERÍA S.A.S | I1: Versión N.07 2024-05-27 FOM303-32
C3: FORMATO DE CAMPO MONITOREO ANALIZADORES AUTOMÁTICOS
A5: PROYECTO: | C5: Aerocivil
A6: MUNICIPIO: | C6: Bogotá | E6: EQUIPO UTILIZADO: | F6: Cabina | G6: COORDENADA NORTE: | H6: 2077821.7
A7: DEPARTAMENTO: | C7: Distrito Capital | E7: S/N: | F7: 2003261452 | G7: COORDENADA OESTE: | H7: 4874451.2
A9: Estación de muestreo | C9: INICIO | E9: FINAL | G9: Tiempo de exposición | H9: DS T°C Shelter (< 2,1) | I9: Observaciones
C10: Fecha | D10: Hora | E10: Fecha | F10: Hora
A11: CA1 Engativa | C11: 46023 | D11: 0 | E11: =C11 -> 46023 | F11: 0.95833333 | G11: =COUNT(INDIRECT("'Dia " & ROW()-10 & "'!C21:C45")) -> 24 | H11: {=IF(G11=24,INDIRECT("'" & "Dia " & ROW()-10 & "'!C47"),"-")} -> 1.0269953
A12: CA1 Engativa | C12: 46024 | D12: 0 | E12: =C12 -> 46024 | F12: 0.95833333 | G12: =COUNT(INDIRECT("'Dia " & ROW()-10 & "'!C21:C45")) -> 24 | H12: {=IF(G12=24,INDIRECT("'" & "Dia " & ROW()-10 & "'!C47"),"-")} -> 0.72720955
A13: CA1 Engativa | C13: 46025 | D13: 0 | E13: =C13 -> 46025 | F13: 0.95833333 | G13: =COUNT(INDIRECT("'Dia " & ROW()-10 & "'!C21:C45")) -> 24 | H13: {=IF(G13=24,INDIRECT("'" & "Dia " & ROW()-10 & "'!C47"),"-")} -> 0.48032543
A14: CA1 Engativa | C14: 46026 | D14: 0 | E14: =C14 -> 46026 | F14: 0.95833333 | G14: =COUNT(INDIRECT("'Dia " & ROW()-10 & "'!C21:C45")) -> 24 | H14: {=IF(G14=24,INDIRECT("'" & "Dia " & ROW()-10 & "'!C47"),"-")} -> 0.55396089
A15: CA1 Engativa | C15: 46027 | D15: 0 | E15: =C15 -> 46027 | F15: 0.95833333 | G15: =COUNT(INDIRECT("'Dia " & ROW()-10 & "'!C21:C45")) -> 24 | H15: {=IF(G15=24,INDIRECT("'" & "Dia " & ROW()-10 & "'!C47"),"-")} -> 0.63695121
A16: CA1 Engativa | C16: 46028 | D16: 0 | E16: =C16 -> 46028 | F16: 0.95833333 | G16: =COUNT(INDIRECT("'Dia " & ROW()-10 & "'!C21:C45")) -> 24 | H16: {=IF(G16=24,INDIRECT("'" & "Dia " & ROW()-10 & "'!C47"),"-")} -> 0.64254902
A17: CA1 Engativa | C17: 46029 | D17: 0 | E17: =C17 -> 46029 | F17: 0.95833333 | G17: =COUNT(INDIRECT("'Dia " & ROW()-10 & "'!C21:C45")) -> 24 | H17: {=IF(G17=24,INDIRECT("'" & "Dia " & ROW()-10 & "'!C47"),"-")} -> 0.6569434
A18: CA1 Engativa | C18: 46030 | D18: 0 | E18: =C18 -> 46030 | F18: 0.95833333 | G18: =COUNT(INDIRECT("'Dia " & ROW()-10 & "'!C21:C45")) -> 24 | H18: {=IF(G18=24,INDIRECT("'" & "Dia " & ROW()-10 & "'!C47"),"-")} -> 1.0357996
A19: CA1 Engativa | C19: 46031 | D19: 0 | E19: =C19 -> 46031 | F19: 0.95833333 | G19: =COUNT(INDIRECT("'Dia " & ROW()-10 & "'!C21:C45")) -> 24 | H19: {=IF(G19=24,INDIRECT("'" & "Dia " & ROW()-10 & "'!C47"),"-")} -> 0.62958461
A20: CA1 Engativa | C20: 46032 | D20: 0 | E20: =C20 -> 46032 | F20: 0.95833333 | G20: =COUNT(INDIRECT("'Dia " & ROW()-10 & "'!C21:C45")) -> 24 | H20: {=IF(G20=24,INDIRECT("'" & "Dia " & ROW()-10 & "'!C47"),"-")} -> 0.66303024
A21: CA1 Engativa | C21: 46033 | D21: 0 | E21: =C21 -> 46033 | F21: 0.95833333 | G21: =COUNT(INDIRECT("'Dia " & ROW()-10 & "'!C21:C45")) -> 24 | H21: {=IF(G21=24,INDIRECT("'" & "Dia " & ROW()-10 & "'!C47"),"-")} -> 1.4422384
A22: CA1 Engativa | C22: 46034 | D22: 0 | E22: =C22 -> 46034 | F22: 0.95833333 | G22: =COUNT(INDIRECT("'Dia " & ROW()-10 & "'!C21:C45")) -> 24 | H22: {=IF(G22=24,INDIRECT("'" & "Dia " & ROW()-10 & "'!C47"),"-")} -> 0.35990263
... A41: CA1 Engativa | C41: 46053 | D41: 0 | E41: =C41 -> 46053 | F41: 0.95833333 | G41: =COUNT(INDIRECT("'Dia " & ROW()-10 & "'!C21:C45")) -> 24 | H41: {=IF(G41=24,INDIRECT("'" & "Dia " & ROW()-10 & "'!C47"),"-")} -> 0.99270517
A42: Elaboró: | B42: Alexander Diaz H. | D42: Revisó | G42: Verificó: | I42: Leonardo Perez D.
B43: Técnico de campo | E43: Coordinador | I43: Consultor
A44: Nota : | B44: Los datos consignados en este documento son válidos únicamente para el proyecto y/o estaciones relacionadas. Cualquier reproducción parcial requiere de la autorización de K2 Ingeniería S.A.S.

Sheet Dia 1
B1: K2 INGENIERÍA S.A.S | F1: Versión N.07 2024-05-27 FOM303-32
B2: FORMATO DE CAMPO MONITOREO ANALIZADORES AUTOMÁTICOS
A7: PROYECTO: | B7: {='FOM303-32-Imprimir'!C5:C5} -> Aerocivil | D7: MUNICIPIO: | E7: Bogotá
A8: ESTACION DE MUESTREO: | B8: CA1 Engativa | D8: DEPARTAMENTO: | E8: Distrito Capital
A9: COORDENADA NORTE: | B9: {='FOM303-32-Imprimir'!H6:H6} -> 2077821.7 | D9: COORDENADA OESTE: | E9: {='FOM303-32-Imprimir'!H7:H7} -> 4874451.2
A10: RESPONSABLE DEL MUESTREO | B10: Leonardo Pérez | D10: ALTURA MSNM: | E10: 2551
A11: FECHA INICIO: | B11: ='FOM303-32-Imprimir'!C11 -> 46023 | D11: HORA INICIO: | E11: 0
A12: FECHA FINAL: | B12: ='FOM303-32-Imprimir'!E11 -> 46023 | D12: HORA FINAL: | E12: 0.95833333
B15: REGISTRO DE LA TEMPERATURA DEL SHELTER HORARIA PARA DETERMINAR DS T°C
B17: PERIODO DE 24 HORAS DESDE LA HORA 0 | C17: REGISTRO DE LA TEMPERATURA DEL SHELTER DE FORMA HORARIO
B21: 0 | C21: 21.683 | D21: 21.683
B22: 1 | C22: 20.855 | D22: 20.855
B23: 2 | C23: 20.029 | D23: 20.029
B24: 3 | C24: 20.233 | D24: 20.233
B25: 4 | C25: 20.186 | D25: 20.186
B26: 5 | C26: 20.137 | D26: 20.137
B27: 6 | C27: 20.045 | D27: 20.045
B28: 7 | C28: 22.618 | D28: 22.618
B29: 8 | C29: 21.733 | D29: 21.733
B30: 9 | C30: 21.024 | D30: 21.024
B31: 10 | C31: 22.887 | D31: 22.887
B32: 11 | C32: 23.667 | D32: 23.667
... B44: 23 | C44: 22.659 | D44: 22.659
B46: PROMEDIO TOTAL T°C | C46: =AVERAGE(C22:C45) -> 21.73387
B47: (DESVIACIÓN ESTÁNDAR) DS T°C | C47: =_xlfn.STDEV.S(C21:C45) -> 1.0269953 | D47: <2.5
B48: VERIFICACIÓN | C48: =IF(ABS(C47)>=2.5,"NO CUMPLE CON DS T°C DEL SHELTER"," CUMPLE CON DS T°C DEL SHELTER") -> CUMPLE CON DS T°C DEL SHELTER

Sheet Dia 2
B1: K2 INGENIERÍA S.A.S | F1: Versión N.07 2024-05-27 FOM303-32
B2: FORMATO DE CAMPO MONITOREO ANALIZADORES AUTOMÁTICOS
A7: PROYECTO: | B7: {='Dia 1'!B7:B7} -> Aerocivil | D7: MUNICIPIO: | E7: {='Dia 1'!E7:E7} -> Bogotá
A8: ESTACION DE MUESTREO: | B8: {='Dia 1'!B8:B8} -> CA1 Engativa | D8: DEPARTAMENTO: | E8: {='Dia 1'!E8:E8} -> Distrito Capital
A9: COORDENADA NORTE: | B9: {='Dia 1'!B9:B9} -> 2077821.7 | D9: COORDENADA OESTE: | E9: {='Dia 1'!E9:E9} -> 4874451.2
A10: RESPONSABLE DEL MUESTREO | B10: {='Dia 1'!B10:B10} -> Leonardo Pérez | D10: ALTURA MSNM: | E10: {='Dia 1'!E10:E10} -> 2551
A11: FECHA INICIO: | B11: ='FOM303-32-Imprimir'!C12 -> 46024 | D11: HORA INICIO: | E11: {='Dia 1'!E11:E11} -> 0
A12: FECHA FINAL: | B12: ='FOM303-32-Imprimir'!E12 -> 46024 | D12: HORA FINAL: | E12: {='Dia 1'!E12:E12} -> 0.95833333
B15: REGISTRO DE LA TEMPERATURA DEL SHELTER HORARIA PARA DETERMINAR DS T°C
B17: PERIODO DE 24 HORAS DESDE LA HORA 0 | C17: REGISTRO DE LA TEMPERATURA DEL SHELTER DE FORMA HORARIO
B21: 0 | C21: 22.72 | D21: 22.72
B22: 1 | C22: 22.581 | D22: 22.581
B23: 2 | C23: 22.376 | D23: 22.376
B24: 3 | C24: 21.996 | D24: 21.996
B25: 4 | C25: 21.155 | D25: 21.155
B26: 5 | C26: 20.635 | D26: 20.635
B27: 6 | C27: 20.665 | D27: 20.665
B28: 7 | C28: 22.637 | D28: 22.637
B29: 8 | C29: 22.661 | D29: 22.661
B30: 9 | C30: 22.617 | D30: 22.617
B31: 10 | C31: 22.346 | D31: 22.346
B32: 11 | C32: 22.394 | D32: 22.394
... B44: 23 | C44: 22.714 | D44: 22.714
B45: 24
B46: PROMEDIO TOTAL T°C | C46: =AVERAGE(C22:C45) -> 22.352783
B47: (DESVIACIÓN ESTÁNDAR) DS T°C | C47: =_xlfn.STDEV.S(C21:C45) -> 0.72720955 | D47: <2.5
B48: VERIFICACIÓN | C48: =IF(ABS(C47)>=2.5,"NO CUMPLE CON DS T°C DEL SHELTER"," CUMPLE CON DS T°C DEL SHELTER") -> CUMPLE CON DS T°C DEL SHELTER

Sheet Dia 3
B1: K2 INGENIERÍA S.A.S | F1: Versión N.07 2024-05-27 FOM303-32
B2: FORMATO DE CAMPO MONITOREO ANALIZADORES AUTOMÁTICOS
A7: PROYECTO: | B7: {='Dia 1'!B7:B7} -> Aerocivil | D7: MUNICIPIO: | E7: {='Dia 1'!E7:E7} -> Bogotá
A8: ESTACION DE MUESTREO: | B8: {='Dia 1'!B8:B8} -> CA1 Engativa | D8: DEPARTAMENTO: | E8: {='Dia 1'!E8:E8} -> Distrito Capital
A9: COORDENADA NORTE: | B9: {='Dia 1'!B9:B9} -> 2077821.7 | D9: COORDENADA OESTE: | E9: {='Dia 1'!E9:E9} -> 4874451.2
A10: RESPONSABLE DEL MUESTREO | B10: {='Dia 1'!B10:B10} -> Leonardo Pérez | D10: ALTURA MSNM: | E10: {='Dia 1'!E10:E10} -> 2551
A11: FECHA INICIO: | B11: ='FOM303-32-Imprimir'!C13 -> 46025 | D11: HORA INICIO: | E11: {='Dia 1'!E11:E11} -> 0
A12: FECHA FINAL: | B12: ='FOM303-32-Imprimir'!E13 -> 46025 | D12: HORA FINAL: | E12: {='Dia 1'!E12:E12} -> 0.95833333
B15: REGISTRO DE LA TEMPERATURA DEL SHELTER HORARIA PARA DETERMINAR DS T°C
B17: PERIODO DE 24 HORAS DESDE LA HORA 0 | C17: REGISTRO DE LA TEMPERATURA DEL SHELTER DE FORMA HORARIO
B21: 0 | C21: 23.105 | D21: 23.105
B22: 1 | C22: 22.377 | D22: 22.377
B23: 2 | C23: 22.343 | D23: 22.343
B24: 3 | C24: 22.613 | D24: 22.613
B25: 4 | C25: 23.176 | D25: 23.176
B26: 5 | C26: 22.844 | D26: 22.844
B27: 6 | C27: 22.889 | D27: 22.889
B28: 7 | C28: 21.861 | D28: 21.861
B29: 8 | C29: 21.942 | D29: 21.942
B30: 9 | C30: 21.463 | D30: 21.463
B31: 10 | C31: 21.681 | D31: 21.681
B32: 11 | C32: 21.366 | D32: 21.366
... B44: 23 | C44: 22.211 | D44: 22.211
B45: 24
B46: PROMEDIO TOTAL T°C | C46: =AVERAGE(C22:C45) -> 22.161261
B47: (DESVIACIÓN ESTÁNDAR) DS T°C | C47: =_xlfn.STDEV.S(C21:C45) -> 0.48032543 | D47: <2.5
B48: VERIFICACIÓN | C48: =IF(ABS(C47)>=2.5,"NO CUMPLE CON DS T°C DEL SHELTER"," CUMPLE CON DS T°C DEL SHELTER") -> CUMPLE CON DS T°C DEL SHELTER

Sheet Dia 4
B1: K2 INGENIERÍA S.A.S | F1: Versión N.07 2024-05-27 FOM303-32
B2: FORMATO DE CAMPO MONITOREO ANALIZADORES AUTOMÁTICOS
A7: PROYECTO: | B7: {='Dia 1'!B7:B7} -> Aerocivil | D7: MUNICIPIO: | E7: {='Dia 1'!E7:E7} -> Bogotá
A8: ESTACION DE MUESTREO: | B8: {='Dia 1'!B8:B8} -> CA1 Engativa | D8: DEPARTAMENTO: | E8: {='Dia 1'!E8:E8} -> Distrito Capital
A9: COORDENADA NORTE: | B9: {='Dia 1'!B9:B9} -> 2077821.7 | D9: COORDENADA OESTE: | E9: {='Dia 1'!E9:E9} -> 4874451.2
A10: RESPONSABLE DEL MUESTREO | B10: {='Dia 1'!B10:B10} -> Leonardo Pérez | D10: ALTURA MSNM: | E10: {='Dia 1'!E10:E10} -> 2551
A11: FECHA INICIO: | B11: ='FOM303-32-Imprimir'!C14 -> 46026 | D11: HORA INICIO: | E11: {='Dia 1'!E11:E11} -> 0
A12: FECHA FINAL: | B12: ='FOM303-32-Imprimir'!E14 -> 46026 | D12: HORA FINAL: | E12: {='Dia 1'!E12:E12} -> 0.95833333
B15: REGISTRO DE LA TEMPERATURA DEL SHELTER HORARIA PARA DETERMINAR DS T°C
B17: PERIODO DE 24 HORAS DESDE LA HORA 0 | C17: REGISTRO DE LA TEMPERATURA DEL SHELTER DE FORMA HORARIO
B21: 0 | C21: 22.983 | D21: 22.983
B22: 1 | C22: 22.328 | D22: 22.328
B23: 2 | C23: 22.474 | D23: 22.474
B24: 3 | C24: 22.628 | D24: 22.628
B25: 4 | C25: 22.404 | D25: 22.404
B26: 5 | C26: 22.985 | D26: 22.985
B27: 6 | C27: 23.261 | D27: 23.261
B28: 7 | C28: 22.307 | D28: 22.307
B29: 8 | C29: 21.211 | D29: 21.211
B30: 9 | C30: 22.287 | D30: 22.287
B31: 10 | C31: 21.835 | D31: 21.835
B32: 11 | C32: 21.953 | D32: 21.953
... B44: 23 | C44: 22.035 | D44: 22.035
B45: 24
B46: PROMEDIO TOTAL T°C | C46: =AVERAGE(C22:C45) -> 22.155174
B47: (DESVIACIÓN ESTÁNDAR) DS T°C | C47: =_xlfn.STDEV.S(C21:C45) -> 0.55396089 | D47: <2.5
B48: VERIFICACIÓN | C48: =IF(ABS(C47)>=2.5,"NO CUMPLE CON DS T°C DEL SHELTER"," CUMPLE CON DS T°C DEL SHELTER") -> CUMPLE CON DS T°C DEL SHELTER

Sheet Dia 5
B1: K2 INGENIERÍA S.A.S | F1: Versión N.07 2024-05-27 FOM303-32
B2: FORMATO DE CAMPO MONITOREO ANALIZADORES AUTOMÁTICOS
A7: PROYECTO: | B7: {='Dia 1'!B7:B7} -> Aerocivil | D7: MUNICIPIO: | E7: {='Dia 1'!E7:E7} -> Bogotá
A8: ESTACION DE MUESTREO: | B8: {='Dia 1'!B8:B8} -> CA1 Engativa | D8: DEPARTAMENTO: | E8: {='Dia 1'!E8:E8} -> Distrito Capital
A9: COORDENADA NORTE: | B9: {='Dia 1'!B9:B9} -> 2077821.7 | D9: COORDENADA OESTE: | E9: {='Dia 1'!E9:E9} -> 4874451.2
A10: RESPONSABLE DEL MUESTREO | B10: {='Dia 1'!B10:B10} -> Leonardo Pérez | D10: ALTURA MSNM: | E10: {='Dia 1'!E10:E10} -> 2551
A11: FECHA INICIO: | B11: ='FOM303-32-Imprimir'!C15 -> 46027 | D11: HORA INICIO: | E11: {='Dia 1'!E11:E11} -> 0
A12: FECHA FINAL: | B12: ='FOM303-32-Imprimir'!E15 -> 46027 | D12: HORA FINAL: | E12: {='Dia 1'!E12:E12} -> 0.95833333
B15: REGISTRO DE LA TEMPERATURA DEL SHELTER HORARIA PARA DETERMINAR DS T°C
B17: PERIODO DE 24 HORAS DESDE LA HORA 0 | C17: REGISTRO DE LA TEMPERATURA DEL SHELTER DE FORMA HORARIO
B21: 0 | C21: 22.061 | D21: 22.061
B22: 1 | C22: 21.972 | D22: 21.972
B23: 2 | C23: 21.922 | D23: 21.922
B24: 3 | C24: 21.961 | D24: 21.961
B25: 4 | C25: 21.926 | D25: 21.926
B26: 5 | C26: 22.468 | D26: 22.468
B27: 6 | C27: 22.626 | D27: 22.626
B28: 7 | C28: 22.074 | D28: 22.074
B29: 8 | C29: 21.055 | D29: 21.055
B30: 9 | C30: 21.033 | D30: 21.033
B31: 10 | C31: 21.555 | D31: 21.555
B32: 11 | C32: 21.759 | D32: 21.759
... B44: 23 | C44: 22.566 | D44: 22.566
B45: 24
B46: PROMEDIO TOTAL T°C | C46: =AVERAGE(C22:C45) -> 22.214217
B47: (DESVIACIÓN ESTÁNDAR) DS T°C | C47: =_xlfn.STDEV.S(C21:C45) -> 0.63695121 | D47: <2.5
B48: VERIFICACIÓN | C48: =IF(ABS(C47)>=2.5,"NO CUMPLE CON DS T°C DEL SHELTER"," CUMPLE CON DS T°C DEL SHELTER") -> CUMPLE CON DS T°C DEL SHELTER

Sheet Dia 6
B1: K2 INGENIERÍA S.A.S | F1: Versión N.07 2024-05-27 FOM303-32
B2: FORMATO DE CAMPO MONITOREO ANALIZADORES AUTOMÁTICOS
A7: PROYECTO: | B7: {='Dia 1'!B7:B7} -> Aerocivil | D7: MUNICIPIO: | E7: {='Dia 1'!E7:E7} -> Bogotá
A8: ESTACION DE MUESTREO: | B8: {='Dia 1'!B8:B8} -> CA1 Engativa | D8: DEPARTAMENTO: | E8: {='Dia 1'!E8:E8} -> Distrito Capital
A9: COORDENADA NORTE: | B9: {='Dia 1'!B9:B9} -> 2077821.7 | D9: COORDENADA OESTE: | E9: {='Dia 1'!E9:E9} -> 4874451.2
A10: RESPONSABLE DEL MUESTREO | B10: {='Dia 1'!B10:B10} -> Leonardo Pérez | D10: ALTURA MSNM: | E10: {='Dia 1'!E10:E10} -> 2551
A11: FECHA INICIO: | B11: ='FOM303-32-Imprimir'!C16 -> 46028 | D11: HORA INICIO: | E11: {='Dia 1'!E11:E11} -> 0
A12: FECHA FINAL: | B12: ='FOM303-32-Imprimir'!E16 -> 46028 | D12: HORA FINAL: | E12: {='Dia 1'!E12:E12} -> 0.95833333
B15: REGISTRO DE LA TEMPERATURA DEL SHELTER HORARIA PARA DETERMINAR DS T°C
B17: PERIODO DE 24 HORAS DESDE LA HORA 0 | C17: REGISTRO DE LA TEMPERATURA DEL SHELTER DE FORMA HORARIO
B21: 0 | C21: 22.878 | D21: 22.878
B22: 1 | C22: 22.376 | D22: 22.376
B23: 2 | C23: 22.711 | D23: 22.711
B24: 3 | C24: 22.535 | D24: 22.535
B25: 4 | C25: 22.413 | D25: 22.413
B26: 5 | C26: 22.52 | D26: 22.52
B27: 6 | C27: 22.546 | D27: 22.546
B28: 7 | C28: 22.756 | D28: 22.756
B29: 8 | C29: 21.79 | D29: 21.79
B30: 9 | C30: 22.07 | D30: 22.07
B31: 10 | C31: 23.718 | D31: 23.718
B32: 11 | C32: 23.787 | D32: 23.787
... B44: 23 | C44: 23.229 | D44: 23.229
B45: 24
B46: PROMEDIO TOTAL T°C | C46: =AVERAGE(C22:C45) -> 22.669043
B47: (DESVIACIÓN ESTÁNDAR) DS T°C | C47: =_xlfn.STDEV.S(C21:C45) -> 0.64254902 | D47: <2.5
B48: VERIFICACIÓN | C48: =IF(ABS(C47)>=2.5,"NO CUMPLE CON DS T°C DEL SHELTER"," CUMPLE CON DS T°C DEL SHELTER") -> CUMPLE CON DS T°C DEL SHELTER

Sheet Dia 7
B1: K2 INGENIERÍA S.A.S | F1: Versión N.07 2024-05-27 FOM303-32
B2: FORMATO DE CAMPO MONITOREO ANALIZADORES AUTOMÁTICOS
A7: PROYECTO: | B7: {='Dia 1'!B7:B7} -> Aerocivil | D7: MUNICIPIO: | E7: {='Dia 1'!E7:E7} -> Bogotá
A8: ESTACION DE MUESTREO: | B8: {='Dia 1'!B8:B8} -> CA1 Engativa | D8: DEPARTAMENTO: | E8: {='Dia 1'!E8:E8} -> Distrito Capital
A9: COORDENADA NORTE: | B9: {='Dia 1'!B9:B9} -> 2077821.7 | D9: COORDENADA OESTE: | E9: {='Dia 1'!E9:E9} -> 4874451.2
A10: RESPONSABLE DEL MUESTREO | B10: {='Dia 1'!B10:B10} -> Leonardo Pérez | D10: ALTURA MSNM: | E10: {='Dia 1'!E10:E10} -> 2551
A11: FECHA INICIO: | B11: ='FOM303-32-Imprimir'!C17 -> 46029 | D11: HORA INICIO: | E11: {='Dia 1'!E11:E11} -> 0
A12: FECHA FINAL: | B12: ='FOM303-32-Imprimir'!E17 -> 46029 | D12: HORA FINAL: | E12: {='Dia 1'!E12:E12} -> 0.95833333
B15: REGISTRO DE LA TEMPERATURA DEL SHELTER HORARIA PARA DETERMINAR DS T°C
B17: PERIODO DE 24 HORAS DESDE LA HORA 0 | C17: REGISTRO DE LA TEMPERATURA DEL SHELTER DE FORMA HORARIO
B21: 0 | C21: 22.591 | D21: 22.591
B22: 1 | C22: 22.685 | D22: 22.685
B23: 2 | C23: 22.618 | D23: 22.618
B24: 3 | C24: 22.85 | D24: 22.85
B25: 4 | C25: 23.021 | D25: 23.021
B26: 5 | C26: 22.978 | D26: 22.978
B27: 6 | C27: 23.074 | D27: 23.074
B28: 7 | C28: 23.357 | D28: 23.357
B29: 8 | C29: 22.307 | D29: 22.307
B30: 9 | C30: 22.033 | D30: 22.033
B31: 10 | C31: 21.839 | D31: 21.839
B32: 11 | C32: 23.566 | D32: 23.566
... B44: 23 | C44: 22.107 | D44: 22.107
B45: 24
B46: PROMEDIO TOTAL T°C | C46: =AVERAGE(C22:C45) -> 22.802043
B47: (DESVIACIÓN ESTÁNDAR) DS T°C | C47: =_xlfn.STDEV.S(C21:C45) -> 0.6569434 | D47: <2.5
B48: VERIFICACIÓN | C48: =IF(ABS(C47)>=2.5,"NO CUMPLE CON DS T°C DEL SHELTER"," CUMPLE CON DS T°C DEL SHELTER") -> CUMPLE CON DS T°C DEL SHELTER

Sheet Dia 8
B1: K2 INGENIERÍA S.A.S | F1: Versión N.07 2024-05-27 FOM303-32
B2: FORMATO DE CAMPO MONITOREO ANALIZADORES AUTOMÁTICOS
A7: PROYECTO: | B7: {='Dia 1'!B7:B7} -> Aerocivil | D7: MUNICIPIO: | E7: {='Dia 1'!E7:E7} -> Bogotá
A8: ESTACION DE MUESTREO: | B8: {='Dia 1'!B8:B8} -> CA1 Engativa | D8: DEPARTAMENTO: | E8: {='Dia 1'!E8:E8} -> Distrito Capital
A9: COORDENADA NORTE: | B9: {='Dia 1'!B9:B9} -> 2077821.7 | D9: COORDENADA OESTE: | E9: {='Dia 1'!E9:E9} -> 4874451.2
A10: RESPONSABLE DEL MUESTREO | B10: {='Dia 1'!B10:B10} -> Leonardo Pérez | D10: ALTURA MSNM: | E10: {='Dia 1'!E10:E10} -> 2551
A11: FECHA INICIO: | B11: ='FOM303-32-Imprimir'!C18 -> 46030 | D11: HORA INICIO: | E11: {='Dia 1'!E11:E11} -> 0
A12: FECHA FINAL: | B12: ='FOM303-32-Imprimir'!E18 -> 46030 | D12: HORA FINAL: | E12: {='Dia 1'!E12:E12} -> 0.95833333
B15: REGISTRO DE LA TEMPERATURA DEL SHELTER HORARIA PARA DETERMINAR DS T°C
B17: PERIODO DE 24 HORAS DESDE LA HORA 0 | C17: REGISTRO DE LA TEMPERATURA DEL SHELTER DE FORMA HORARIO
B21: 0 | C21: 22.383 | D21: 22.383
B22: 1 | C22: 21.816 | D22: 21.816
B23: 2 | C23: 21.063 | D23: 21.063
B24: 3 | C24: 20.466 | D24: 20.466
B25: 4 | C25: 20.338 | D25: 20.338
B26: 5 | C26: 20.876 | D26: 20.876
B27: 6 | C27: 21.033 | D27: 21.033
B28: 7 | C28: 22.557 | D28: 22.557
B29: 8 | C29: 22.574 | D29: 22.574
B30: 9 | C30: 22.113 | D30: 22.113
B31: 10 | C31: 21.766 | D31: 21.766
B32: 11 | C32: 22.685 | D32: 22.685
... B44: 23 | C44: 22.579 | D44: 22.579
B45: 24
B46: PROMEDIO TOTAL T°C | C46: =AVERAGE(C22:C45) -> 22.38013
B47: (DESVIACIÓN ESTÁNDAR) DS T°C | C47: =_xlfn.STDEV.S(C21:C45) -> 1.0357996 | D47: <2.5
B48: VERIFICACIÓN | C48: =IF(ABS(C47)>=2.5,"NO CUMPLE CON DS T°C DEL SHELTER"," CUMPLE CON DS T°C DEL SHELTER") -> CUMPLE CON DS T°C DEL SHELTER

Sheet Dia 9
B1: K2 INGENIERÍA S.A.S | F1: Versión N.07 2024-05-27 FOM303-32
B2: FORMATO DE CAMPO MONITOREO ANALIZADORES AUTOMÁTICOS
A7: PROYECTO: | B7: {='Dia 1'!B7:B7} -> Aerocivil | D7: MUNICIPIO: | E7: {='Dia 1'!E7:E7} -> Bogotá
A8: ESTACION DE MUESTREO: | B8: {='Dia 1'!B8:B8} -> CA1 Engativa | D8: DEPARTAMENTO: | E8: {='Dia 1'!E8:E8} -> Distrito Capital
A9: COORDENADA NORTE: | B9: {='Dia 1'!B9:B9} -> 2077821.7 | D9: COORDENADA OESTE: | E9: {='Dia 1'!E9:E9} -> 4874451.2
A10: RESPONSABLE DEL MUESTREO | B10: {='Dia 1'!B10:B10} -> Leonardo Pérez | D10: ALTURA MSNM: | E10: {='Dia 1'!E10:E10} -> 2551
A11: FECHA INICIO: | B11: ='FOM303-32-Imprimir'!C19 -> 46031 | D11: HORA INICIO: | E11: {='Dia 1'!E11:E11} -> 0
A12: FECHA FINAL: | B12: ='FOM303-32-Imprimir'!E19 -> 46031 | D12: HORA FINAL: | E12: {='Dia 1'!E12:E12} -> 0.95833333
B15: REGISTRO DE LA TEMPERATURA DEL SHELTER HORARIA PARA DETERMINAR DS T°C
B17: PERIODO DE 24 HORAS DESDE LA HORA 0 | C17: REGISTRO DE LA TEMPERATURA DEL SHELTER DE FORMA HORARIO
B21: 0 | C21: 22.059 | D21: 22.059
B22: 1 | C22: 22.105 | D22: 22.105
B23: 2 | C23: 22.004 | D23: 22.004
B24: 3 | C24: 21.37 | D24: 21.37
B25: 4 | C25: 21.214 | D25: 21.214
B26: 5 | C26: 20.97 | D26: 20.97
B27: 6 | C27: 21.296 | D27: 21.296
B28: 7 | C28: 22.846 | D28: 22.846
B29: 8 | C29: 22.183 | D29: 22.183
B30: 9 | C30: 21.752 | D30: 21.752
B31: 10 | C31: 22.557 | D31: 22.557
B32: 11 | C32: 21.813 | D32: 21.813
... B44: 23 | C44: 22.361 | D44: 22.361
B45: 24
B46: PROMEDIO TOTAL T°C | C46: =AVERAGE(C22:C45) -> 22.095
B47: (DESVIACIÓN ESTÁNDAR) DS T°C | C47: =_xlfn.STDEV.S(C21:C45) -> 0.62958461 | D47: <2.5
B48: VERIFICACIÓN | C48: =IF(ABS(C47)>=2.5,"NO CUMPLE CON DS T°C DEL SHELTER"," CUMPLE CON DS T°C DEL SHELTER") -> CUMPLE CON DS T°C DEL SHELTER

Sheet Dia 10
B1: K2 INGENIERÍA S.A.S | F1: Versión N.07 2024-05-27 FOM303-32
B2: FORMATO DE CAMPO MONITOREO ANALIZADORES AUTOMÁTICOS
A7: PROYECTO: | B7: {='Dia 1'!B7:B7} -> Aerocivil | D7: MUNICIPIO: | E7: {='Dia 1'!E7:E7} -> Bogotá
A8: ESTACION DE MUESTREO: | B8: {='Dia 1'!B8:B8} -> CA1 Engativa | D8: DEPARTAMENTO: | E8: {='Dia 1'!E8:E8} -> Distrito Capital
A9: COORDENADA NORTE: | B9: {='Dia 1'!B9:B9} -> 2077821.7 | D9: COORDENADA OESTE: | E9: {='Dia 1'!E9:E9} -> 4874451.2
A10: RESPONSABLE DEL MUESTREO | B10: {='Dia 1'!B10:B10} -> Leonardo Pérez | D10: ALTURA MSNM: | E10: {='Dia 1'!E10:E10} -> 2551
A11: FECHA INICIO: | B11: ='FOM303-32-Imprimir'!C20 -> 46032 | D11: HORA INICIO: | E11: {='Dia 1'!E11:E11} -> 0
A12: FECHA FINAL: | B12: ='FOM303-32-Imprimir'!E20 -> 46032 | D12: HORA FINAL: | E12: {='Dia 1'!E12:E12} -> 0.95833333
B15: REGISTRO DE LA TEMPERATURA DEL SHELTER HORARIA PARA DETERMINAR DS T°C
B17: PERIODO DE 24 HORAS DESDE LA HORA 0 | C17: REGISTRO DE LA TEMPERATURA DEL SHELTER DE FORMA HORARIO
B21: 0 | C21: 22.198 | D21: 22.198
B22: 1 | C22: 22.485 | D22: 22.485
B23: 2 | C23: 22.867 | D23: 22.867
B24: 3 | C24: 22.513 | D24: 22.513
B25: 4 | C25: 21.948 | D25: 21.948
B26: 5 | C26: 21.935 | D26: 21.935
B27: 6 | C27: 22.337 | D27: 22.337
B28: 7 | C28: 23.081 | D28: 23.081
B29: 8 | C29: 21.985 | D29: 21.985
B30: 9 | C30: 22.798 | D30: 22.798
B31: 10 | C31: 23.688 | D31: 23.688
B32: 11 | C32: 21.722 | D32: 21.722
... B44: 23 | C44: 20.887 | D44: 20.887
B45: 24
B46: PROMEDIO TOTAL T°C | C46: =AVERAGE(C22:C45) -> 22.342696
B47: (DESVIACIÓN ESTÁNDAR) DS T°C | C47: =_xlfn.STDEV.S(C21:C45) -> 0.66303024 | D47: <2.5
B48: VERIFICACIÓN | C48: =IF(ABS(C47)>=2.5,"NO CUMPLE CON DS T°C DEL SHELTER"," CUMPLE CON DS T°C DEL SHELTER") -> CUMPLE CON DS T°C DEL SHELTER

Sheet Dia 11
B1: K2 INGENIERÍA S.A.S | F1: Versión N.07 2024-05-27 FOM303-32
B2: FORMATO DE CAMPO MONITOREO ANALIZADORES AUTOMÁTICOS
A7: PROYECTO: | B7: {='Dia 1'!B7:B7} -> Aerocivil | D7: MUNICIPIO: | E7: {='Dia 1'!E7:E7} -> Bogotá
A8: ESTACION DE MUESTREO: | B8: {='Dia 1'!B8:B8} -> CA1 Engativa | D8: DEPARTAMENTO: | E8: {='Dia 1'!E8:E8} -> Distrito Capital
A9: COORDENADA NORTE: | B9: {='Dia 1'!B9:B9} -> 2077821.7 | D9: COORDENADA OESTE: | E9: {='Dia 1'!E9:E9} -> 4874451.2
A10: RESPONSABLE DEL MUESTREO | B10: {='Dia 1'!B10:B10} -> Leonardo Pérez | D10: ALTURA MSNM: | E10: {='Dia 1'!E10:E10} -> 2551
A11: FECHA INICIO: | B11: ='FOM303-32-Imprimir'!C21 -> 46033 | D11: HORA INICIO: | E11: {='Dia 1'!E11:E11} -> 0
A12: FECHA FINAL: | B12: ='FOM303-32-Imprimir'!E21 -> 46033 | D12: HORA FINAL: | E12: {='Dia 1'!E12:E12} -> 0.95833333
B15: REGISTRO DE LA TEMPERATURA DEL SHELTER HORARIA PARA DETERMINAR DS T°C
B17: PERIODO DE 24 HORAS DESDE LA HORA 0 | C17: REGISTRO DE LA TEMPERATURA DEL SHELTER DE FORMA HORARIO
B21: 0 | C21: 22.122 | D21: 22.122
B22: 1 | C22: 21.217 | D22: 21.217
B23: 2 | C23: 20.335 | D23: 20.335
B24: 3 | C24: 19.82 | D24: 19.82
B25: 4 | C25: 19.787 | D25: 19.787
B26: 5 | C26: 19.702 | D26: 19.702
B27: 6 | C27: 21.317 | D27: 21.317
B28: 7 | C28: 23.758 | D28: 23.758
B29: 8 | C29: 22.67 | D29: 22.67
B30: 9 | C30: 23.711 | D30: 23.711
B31: 10 | C31: 23.801 | D31: 23.801
B32: 11 | C32: 23.952 | D32: 23.952
... B44: 23 | C44: 22.909 | D44: 22.909
B45: 24
B46: PROMEDIO TOTAL T°C | C46: =AVERAGE(C22:C45) -> 22.637522
B47: (DESVIACIÓN ESTÁNDAR) DS T°C | C47: =_xlfn.STDEV.S(C21:C45) -> 1.4422384 | D47: <2.5
B48: VERIFICACIÓN | C48: =IF(ABS(C47)>=2.5,"NO CUMPLE CON DS T°C DEL SHELTER"," CUMPLE CON DS T°C DEL SHELTER") -> CUMPLE CON DS T°C DEL SHELTER

Sheet Dia 12
B1: K2 INGENIERÍA S.A.S | F1: Versión N.07 2024-05-27 FOM303-32
B2: FORMATO DE CAMPO MONITOREO ANALIZADORES AUTOMÁTICOS
A7: PROYECTO: | B7: {='Dia 1'!B7:B7} -> Aerocivil | D7: MUNICIPIO: | E7: {='Dia 1'!E7:E7} -> Bogotá
A8: ESTACION DE MUESTREO: | B8: {='Dia 1'!B8:B8} -> CA1 Engativa | D8: DEPARTAMENTO: | E8: {='Dia 1'!E8:E8} -> Distrito Capital
A9: COORDENADA NORTE: | B9: {='Dia 1'!B9:B9} -> 2077821.7 | D9: COORDENADA OESTE: | E9: {='Dia 1'!E9:E9} -> 4874451.2
A10: RESPONSABLE DEL MUESTREO | B10: {='Dia 1'!B10:B10} -> Leonardo Pérez | D10: ALTURA MSNM: | E10: {='Dia 1'!E10:E10} -> 2551
A11: FECHA INICIO: | B11: ='FOM303-32-Imprimir'!C22 -> 46034 | D11: HORA INICIO: | E11: {='Dia 1'!E11:E11} -> 0
A12: FECHA FINAL: | B12: ='FOM303-32-Imprimir'!E22 -> 46034 | D12: HORA FINAL: | E12: {='Dia 1'!E12:E12} -> 0.95833333
B15: REGISTRO DE LA TEMPERATURA DEL SHELTER HORARIA PARA DETERMINAR DS T°C
B17: PERIODO DE 24 HORAS DESDE LA HORA 0 | C17: REGISTRO DE LA TEMPERATURA DEL SHELTER DE FORMA HORARIO
B21: 0 | C21: 23.431 | D21: 23.431
B22: 1 | C22: 23.809 | D22: 23.809
B23: 2 | C23: 24.035 | D23: 24.035
B24: 3 | C24: 24.14 | D24: 24.14
B25: 4 | C25: 23.82 | D25: 23.82
B26: 5 | C26: 23.581 | D26: 23.581
B27: 6 | C27: 23.924 | D27: 23.924
B28: 7 | C28: 23.884 | D28: 23.884
B29: 8 | C29: 23.239 | D29: 23.239
B30: 9 | C30: 23.572 | D30: 23.572
B31: 10 | C31: 23.081 | D31: 23.081
B32: 11 | C32: 23.574 | D32: 23.574
... B44: 23 | C44: 22.642 | D44: 22.642
B45: 24
B46: PROMEDIO TOTAL T°C | C46: =AVERAGE(C22:C45) -> 23.536304
B47: (DESVIACIÓN ESTÁNDAR) DS T°C | C47: =_xlfn.STDEV.S(C21:C45) -> 0.35990263 | D47: <2.5
B48: VERIFICACIÓN | C48: =IF(ABS(C47)>=2.5,"NO CUMPLE CON DS T°C DEL SHELTER"," CUMPLE CON DS T°C DEL SHELTER") -> CUMPLE CON DS T°C DEL SHELTER

Sheet Dia 13
B1: K2 INGENIERÍA S.A.S | F1: Versión N.07 2024-05-27 FOM303-32
B2: FORMATO DE CAMPO MONITOREO ANALIZADORES AUTOMÁTICOS
A7: PROYECTO: | B7: {='Dia 1'!B7:B7} -> Aerocivil | D7: MUNICIPIO: | E7: {='Dia 1'!E7:E7} -> Bogotá
A8: ESTACION DE MUESTREO: | B8: {='Dia 1'!B8:B8} -> CA1 Engativa | D8: DEPARTAMENTO: | E8: {='Dia 1'!E8:E8} -> Distrito Capital
A9: COORDENADA NORTE: | B9: {='Dia 1'!B9:B9} -> 2077821.7 | D9: COORDENADA OESTE: | E9: {='Dia 1'!E9:E9} -> 4874451.2
A10: RESPONSABLE DEL MUESTREO | B10: {='Dia 1'!B10:B10} -> Leonardo Pérez | D10: ALTURA MSNM: | E10: {='Dia 1'!E10:E10} -> 2551
A11: FECHA INICIO: | B11: ='FOM303-32-Imprimir'!C23 -> 46035 | D11: HORA INICIO: | E11: {='Dia 1'!E11:E11} -> 0
A12: FECHA FINAL: | B12: ='FOM303-32-Imprimir'!E23 -> 46035 | D12: HORA FINAL: | E12: {='Dia 1'!E12:E12} -> 0.95833333
B15: REGISTRO DE LA TEMPERATURA DEL SHELTER HORARIA PARA DETERMINAR DS T°C
B17: PERIODO DE 24 HORAS DESDE LA HORA 0 | C17: REGISTRO DE LA TEMPERATURA DEL SHELTER DE FORMA HORARIO
B21: 0 | C21: 22.196 | D21: 22.196
B22: 1 | C22: 22.13 | D22: 22.13
B23: 2 | C23: 22.415 | D23: 22.415
B24: 3 | C24: 22.396 | D24: 22.396
B25: 4 | C25: 21.896 | D25: 21.896
B26: 5 | C26: 22.402 | D26: 22.402
B27: 6 | C27: 23.191 | D27: 23.191
B28: 7 | C28: 23.566 | D28: 23.566
B29: 8 | C29: 22.996 | D29: 22.996
B30: 9 | C30: 23.055 | D30: 23.055
B31: 10 | C31: 23.804 | D31: 23.804
B32: 11 | C32: 23.355 | D32: 23.355
... B44: 23 | C44: 23.838 | D44: 23.838
B45: 24
B46: PROMEDIO TOTAL T°C | C46: =AVERAGE(C22:C45) -> 23.28587
B47: (DESVIACIÓN ESTÁNDAR) DS T°C | C47: =_xlfn.STDEV.S(C21:C45) -> 0.6386421 | D47: <2.5
B48: VERIFICACIÓN | C48: =IF(ABS(C47)>=2.5,"NO CUMPLE CON DS T°C DEL SHELTER"," CUMPLE CON DS T°C DEL SHELTER") -> CUMPLE CON DS T°C DEL SHELTER

Sheet Dia 14
B1: K2 INGENIERÍA S.A.S | F1: Versión N.07 2024-05-27 FOM303-32
B2: FORMATO DE CAMPO MONITOREO ANALIZADORES AUTOMÁTICOS
A7: PROYECTO: | B7: {='Dia 1'!B7:B7} -> Aerocivil | D7: MUNICIPIO: | E7: {='Dia 1'!E7:E7} -> Bogotá
A8: ESTACION DE MUESTREO: | B8: {='Dia 1'!B8:B8} -> CA1 Engativa | D8: DEPARTAMENTO: | E8: {='Dia 1'!E8:E8} -> Distrito Capital
A9: COORDENADA NORTE: | B9: {='Dia 1'!B9:B9} -> 2077821.7 | D9: COORDENADA OESTE: | E9: {='Dia 1'!E9:E9} -> 4874451.2
A10: RESPONSABLE DEL MUESTREO | B10: {='Dia 1'!B10:B10} -> Leonardo Pérez | D10: ALTURA MSNM: | E10: {='Dia 1'!E10:E10} -> 2551
A11: FECHA INICIO: | B11: ='FOM303-32-Imprimir'!C24 -> 46036 | D11: HORA INICIO: | E11: {='Dia 1'!E11:E11} -> 0
A12: FECHA FINAL: | B12: ='FOM303-32-Imprimir'!E24 -> 46036 | D12: HORA FINAL: | E12: {='Dia 1'!E12:E12} -> 0.95833333
B15: REGISTRO DE LA TEMPERATURA DEL SHELTER HORARIA PARA DETERMINAR DS T°C
B17: PERIODO DE 24 HORAS DESDE LA HORA 0 | C17: REGISTRO DE LA TEMPERATURA DEL SHELTER DE FORMA HORARIO
B21: 0 | C21: 24.082 | D21: 24.082
B22: 1 | C22: 23.923 | D22: 23.923
B23: 2 | C23: 24.207 | D23: 24.207
B24: 3 | C24: 24.344 | D24: 24.344
B25: 4 | C25: 23.605 | D25: 23.605
B26: 5 | C26: 23.929 | D26: 23.929
B27: 6 | C27: 23.937 | D27: 23.937
B28: 7 | C28: 23.812 | D28: 23.812
B29: 8 | C29: 23.277 | D29: 23.277
B30: 9 | C30: 23.64 | D30: 23.64
B31: 10 | C31: 23.816 | D31: 23.816
B32: 11 | C32: 24.109 | D32: 24.109
... B44: 23 | C44: 23.707 | D44: 23.707
B45: 24
B46: PROMEDIO TOTAL T°C | C46: =AVERAGE(C22:C45) -> 23.686087
B47: (DESVIACIÓN ESTÁNDAR) DS T°C | C47: =_xlfn.STDEV.S(C21:C45) -> 0.4899921 | D47: <2.5
B48: VERIFICACIÓN | C48: =IF(ABS(C47)>=2.5,"NO CUMPLE CON DS T°C DEL SHELTER"," CUMPLE CON DS T°C DEL SHELTER") -> CUMPLE CON DS T°C DEL SHELTER

Sheet Dia 15
B1: K2 INGENIERÍA S.A.S | F1: Versión N.07 2024-05-27 FOM303-32
B2: FORMATO DE CAMPO MONITOREO ANALIZADORES AUTOMÁTICOS
A7: PROYECTO: | B7: {='Dia 1'!B7:B7} -> Aerocivil | D7: MUNICIPIO: | E7: {='Dia 1'!E7:E7} -> Bogotá
A8: ESTACION DE MUESTREO: | B8: {='Dia 1'!B8:B8} -> CA1 Engativa | D8: DEPARTAMENTO: | E8: {='Dia 1'!E8:E8} -> Distrito Capital
A9: COORDENADA NORTE: | B9: {='Dia 1'!B9:B9} -> 2077821.7 | D9: COORDENADA OESTE: | E9: {='Dia 1'!E9:E9} -> 4874451.2
A10: RESPONSABLE DEL MUESTREO | B10: {='Dia 1'!B10:B10} -> Leonardo Pérez | D10: ALTURA MSNM: | E10: {='Dia 1'!E10:E10} -> 2551
A11: FECHA INICIO: | B11: ='FOM303-32-Imprimir'!C25 -> 46037 | D11: HORA INICIO: | E11: {='Dia 1'!E11:E11} -> 0
A12: FECHA FINAL: | B12: ='FOM303-32-Imprimir'!E25 -> 46037 | D12: HORA FINAL: | E12: {='Dia 1'!E12:E12} -> 0.95833333
B15: REGISTRO DE LA TEMPERATURA DEL SHELTER HORARIA PARA DETERMINAR DS T°C
B17: PERIODO DE 24 HORAS DESDE LA HORA 0 | C17: REGISTRO DE LA TEMPERATURA DEL SHELTER DE FORMA HORARIO
B21: 0 | C21: 23.777 | D21: 23.777
B22: 1 | C22: 23.865 | D22: 23.865
B23: 2 | C23: 24.165 | D23: 24.165
B24: 3 | C24: 23.398 | D24: 23.398
B25: 4 | C25: 22.385 | D25: 22.385
B26: 5 | C26: 21.613 | D26: 21.613
B27: 6 | C27: 21.596 | D27: 21.596
B28: 7 | C28: 23.462 | D28: 23.462
B29: 8 | C29: 23.169 | D29: 23.169
B30: 9 | C30: 22.806 | D30: 22.806
B31: 10 | C31: 23.287 | D31: 23.287
B32: 11 | C32: 23.838 | D32: 23.838
... B44: 23 | C44: 24.298 | D44: 24.298
B45: 24
B46: PROMEDIO TOTAL T°C | C46: =AVERAGE(C22:C45) -> 23.265609
B47: (DESVIACIÓN ESTÁNDAR) DS T°C | C47: =_xlfn.STDEV.S(C21:C45) -> 0.7320854 | D47: <2.5
B48: VERIFICACIÓN | C48: =IF(ABS(C47)>=2.5,"NO CUMPLE CON DS T°C DEL SHELTER"," CUMPLE CON DS T°C DEL SHELTER") -> CUMPLE CON DS T°C DEL SHELTER

Sheet Dia 16
B1: K2 INGENIERÍA S.A.S | F1: Versión N.07 2024-05-27 FOM303-32
B2: FORMATO DE CAMPO MONITOREO ANALIZADORES AUTOMÁTICOS
A7: PROYECTO: | B7: {='Dia 1'!B7:B7} -> Aerocivil | D7: MUNICIPIO: | E7: {='Dia 1'!E7:E7} -> Bogotá
A8: ESTACION DE MUESTREO: | B8: {='Dia 1'!B8:B8} -> CA1 Engativa | D8: DEPARTAMENTO: | E8: {='Dia 1'!E8:E8} -> Distrito Capital
A9: COORDENADA NORTE: | B9: {='Dia 1'!B9:B9} -> 2077821.7 | D9: COORDENADA OESTE: | E9: {='Dia 1'!E9:E9} -> 4874451.2
A10: RESPONSABLE DEL MUESTREO | B10: {='Dia 1'!B10:B10} -> Leonardo Pérez | D10: ALTURA MSNM: | E10: {='Dia 1'!E10:E10} -> 2551
A11: FECHA INICIO: | B11: ='FOM303-32-Imprimir'!C26 -> 46038 | D11: HORA INICIO: | E11: {='Dia 1'!E11:E11} -> 0
A12: FECHA FINAL: | B12: ='FOM303-32-Imprimir'!E26 -> 46038 | D12: HORA FINAL: | E12: {='Dia 1'!E12:E12} -> 0.95833333
B15: REGISTRO DE LA TEMPERATURA DEL SHELTER HORARIA PARA DETERMINAR DS T°C
B17: PERIODO DE 24 HORAS DESDE LA HORA 0 | C17: REGISTRO DE LA TEMPERATURA DEL SHELTER DE FORMA HORARIO
B21: 0 | C21: 24.141 | D21: 24.141
B22: 1 | C22: 23.557 | D22: 23.557
B23: 2 | C23: 22.672 | D23: 22.672
B24: 3 | C24: 22.804 | D24: 22.804
B25: 4 | C25: 22.741 | D25: 22.741
B26: 5 | C26: 22.358 | D26: 22.358
B27: 6 | C27: 22.504 | D27: 22.504
B28: 7 | C28: 23.32 | D28: 23.32
B29: 8 | C29: 23.812 | D29: 23.812
B30: 9 | C30: 23.718 | D30: 23.718
B31: 10 | C31: 23.494 | D31: 23.494
B32: 11 | C32: 22.737 | D32: 22.737
... B44: 23 | C44: 23.029 | D44: 23.029
B45: 24
B46: PROMEDIO TOTAL T°C | C46: =AVERAGE(C22:C45) -> 23.207652
B47: (DESVIACIÓN ESTÁNDAR) DS T°C | C47: =_xlfn.STDEV.S(C21:C45) -> 0.53854918 | D47: <2.5
B48: VERIFICACIÓN | C48: =IF(ABS(C47)>=2.5,"NO CUMPLE CON DS T°C DEL SHELTER"," CUMPLE CON DS T°C DEL SHELTER") -> CUMPLE CON DS T°C DEL SHELTER

Sheet Dia 17
B1: K2 INGENIERÍA S.A.S | F1: Versión N.07 2024-05-27 FOM303-32
B2: FORMATO DE CAMPO MONITOREO ANALIZADORES AUTOMÁTICOS
A7: PROYECTO: | B7: {='Dia 1'!B7:B7} -> Aerocivil | D7: MUNICIPIO: | E7: {='Dia 1'!E7:E7} -> Bogotá
A8: ESTACION DE MUESTREO: | B8: {='Dia 1'!B8:B8} -> CA1 Engativa | D8: DEPARTAMENTO: | E8: {='Dia 1'!E8:E8} -> Distrito Capital
A9: COORDENADA NORTE: | B9: {='Dia 1'!B9:B9} -> 2077821.7 | D9: COORDENADA OESTE: | E9: {='Dia 1'!E9:E9} -> 4874451.2
A10: RESPONSABLE DEL MUESTREO | B10: {='Dia 1'!B10:B10} -> Leonardo Pérez | D10: ALTURA MSNM: | E10: {='Dia 1'!E10:E10} -> 2551
A11: FECHA INICIO: | B11: ='FOM303-32-Imprimir'!C27 -> 46039 | D11: HORA INICIO: | E11: {='Dia 1'!E11:E11} -> 0
A12: FECHA FINAL: | B12: ='FOM303-32-Imprimir'!E27 -> 46039 | D12: HORA FINAL: | E12: {='Dia 1'!E12:E12} -> 0.95833333
B15: REGISTRO DE LA TEMPERATURA DEL SHELTER HORARIA PARA DETERMINAR DS T°C
B17: PERIODO DE 24 HORAS DESDE LA HORA 0 | C17: REGISTRO DE LA TEMPERATURA DEL SHELTER DE FORMA HORARIO
B21: 0 | C21: 22.587 | D21: 22.587
B22: 1 | C22: 21.663 | D22: 21.663
B23: 2 | C23: 20.765 | D23: 20.765
B24: 3 | C24: 20.118 | D24: 20.118
B25: 4 | C25: 20.016 | D25: 20.016
B26: 5 | C26: 20.175 | D26: 20.175
B27: 6 | C27: 20.39 | D27: 20.39
B28: 7 | C28: 23.766 | D28: 23.766
B29: 8 | C29: 23.176 | D29: 23.176
B30: 9 | C30: 23.783 | D30: 23.783
B31: 10 | C31: 23.712 | D31: 23.712
B32: 11 | C32: 23.782 | D32: 23.782
... B44: 23 | C44: 24.127 | D44: 24.127
B45: 24
B46: PROMEDIO TOTAL T°C | C46: =AVERAGE(C22:C45) -> 22.852913
B47: (DESVIACIÓN ESTÁNDAR) DS T°C | C47: =_xlfn.STDEV.S(C21:C45) -> 1.4394936 | D47: <2.5
B48: VERIFICACIÓN | C48: =IF(ABS(C47)>=2.5,"NO CUMPLE CON DS T°C DEL SHELTER"," CUMPLE CON DS T°C DEL SHELTER") -> CUMPLE CON DS T°C DEL SHELTER

Sheet Dia 18
B1: K2 INGENIERÍA S.A.S | F1: Versión N.07 2024-05-27 FOM303-32
B2: FORMATO DE CAMPO MONITOREO ANALIZADORES AUTOMÁTICOS
A7: PROYECTO: | B7: {='Dia 1'!B7:B7} -> Aerocivil | D7: MUNICIPIO: | E7: {='Dia 1'!E7:E7} -> Bogotá
A8: ESTACION DE MUESTREO: | B8: {='Dia 1'!B8:B8} -> CA1 Engativa | D8: DEPARTAMENTO: | E8: {='Dia 1'!E8:E8} -> Distrito Capital
A9: COORDENADA NORTE: | B9: {='Dia 1'!B9:B9} -> 2077821.7 | D9: COORDENADA OESTE: | E9: {='Dia 1'!E9:E9} -> 4874451.2
A10: RESPONSABLE DEL MUESTREO | B10: {='Dia 1'!B10:B10} -> Leonardo Pérez | D10: ALTURA MSNM: | E10: {='Dia 1'!E10:E10} -> 2551
A11: FECHA INICIO: | B11: ='FOM303-32-Imprimir'!C28 -> 46040 | D11: HORA INICIO: | E11: {='Dia 1'!E11:E11} -> 0
A12: FECHA FINAL: | B12: ='FOM303-32-Imprimir'!E28 -> 46040 | D12: HORA FINAL: | E12: {='Dia 1'!E12:E12} -> 0.95833333
B15: REGISTRO DE LA TEMPERATURA DEL SHELTER HORARIA PARA DETERMINAR DS T°C
B17: PERIODO DE 24 HORAS DESDE LA HORA 0 | C17: REGISTRO DE LA TEMPERATURA DEL SHELTER DE FORMA HORARIO
B21: 0 | C21: 23.942 | D21: 23.942
B22: 1 | C22: 23.09 | D22: 23.09
B23: 2 | C23: 22.105 | D23: 22.105
B24: 3 | C24: 20.97 | D24: 20.97
B25: 4 | C25: 20.042 | D25: 20.042
B26: 5 | C26: 19.762 | D26: 19.762
B27: 6 | C27: 20.851 | D27: 20.851
B28: 7 | C28: 23.751 | D28: 23.751
B29: 8 | C29: 22.657 | D29: 22.657
B30: 9 | C30: 23.566 | D30: 23.566
B31: 10 | C31: 23.837 | D31: 23.837
B32: 11 | C32: 24.03 | D32: 24.03
... B44: 23 | C44: 24.072 | D44: 24.072
B45: 24
B46: PROMEDIO TOTAL T°C | C46: =AVERAGE(C22:C45) -> 22.942261
B47: (DESVIACIÓN ESTÁNDAR) DS T°C | C47: =_xlfn.STDEV.S(C21:C45) -> 1.3223566 | D47: <2.5
B48: VERIFICACIÓN | C48: =IF(ABS(C47)>=2.5,"NO CUMPLE CON DS T°C DEL SHELTER"," CUMPLE CON DS T°C DEL SHELTER") -> CUMPLE CON DS T°C DEL SHELTER

Sheet Dia 19
B1: K2 INGENIERÍA S.A.S | F1: Versión N.07 2024-05-27 FOM303-32
B2: FORMATO DE CAMPO MONITOREO ANALIZADORES AUTOMÁTICOS
A7: PROYECTO: | B7: {='Dia 1'!B7:B7} -> Aerocivil | D7: MUNICIPIO: | E7: {='Dia 1'!E7:E7} -> Bogotá
A8: ESTACION DE MUESTREO: | B8: {='Dia 1'!B8:B8} -> CA1 Engativa | D8: DEPARTAMENTO: | E8: {='Dia 1'!E8:E8} -> Distrito Capital
A9: COORDENADA NORTE: | B9: {='Dia 1'!B9:B9} -> 2077821.7 | D9: COORDENADA OESTE: | E9: {='Dia 1'!E9:E9} -> 4874451.2
A10: RESPONSABLE DEL MUESTREO | B10: {='Dia 1'!B10:B10} -> Leonardo Pérez | D10: ALTURA MSNM: | E10: {='Dia 1'!E10:E10} -> 2551
A11: FECHA INICIO: | B11: ='FOM303-32-Imprimir'!C29 -> 46041 | D11: HORA INICIO: | E11: {='Dia 1'!E11:E11} -> 0
A12: FECHA FINAL: | B12: ='FOM303-32-Imprimir'!E29 -> 46041 | D12: HORA FINAL: | E12: {='Dia 1'!E12:E12} -> 0.95833333
B15: REGISTRO DE LA TEMPERATURA DEL SHELTER HORARIA PARA DETERMINAR DS T°C
B17: PERIODO DE 24 HORAS DESDE LA HORA 0 | C17: REGISTRO DE LA TEMPERATURA DEL SHELTER DE FORMA HORARIO
B21: 0 | C21: 24.166 | D21: 24.166
B22: 1 | C22: 23.881 | D22: 23.881
B23: 2 | C23: 23.124 | D23: 23.124
B24: 3 | C24: 22.526 | D24: 22.526
B25: 4 | C25: 22.144 | D25: 22.144
B26: 5 | C26: 21.826 | D26: 21.826
B27: 6 | C27: 22.189 | D27: 22.189
B28: 7 | C28: 23.44 | D28: 23.44
B29: 8 | C29: 22.804 | D29: 22.804
B30: 9 | C30: 23.159 | D30: 23.159
B31: 10 | C31: 22.831 | D31: 22.831
B32: 11 | C32: 22.905 | D32: 22.905
... B44: 23 | C44: 24.263 | D44: 24.263
B45: 24
B46: PROMEDIO TOTAL T°C | C46: =AVERAGE(C22:C45) -> 23.193957
B47: (DESVIACIÓN ESTÁNDAR) DS T°C | C47: =_xlfn.STDEV.S(C21:C45) -> 0.67180956 | D47: <2.5
B48: VERIFICACIÓN | C48: =IF(ABS(C47)>=2.5,"NO CUMPLE CON DS T°C DEL SHELTER"," CUMPLE CON DS T°C DEL SHELTER") -> CUMPLE CON DS T°C DEL SHELTER

Sheet Dia 20
B1: K2 INGENIERÍA S.A.S | F1: Versión N.07 2024-05-27 FOM303-32
B2: FORMATO DE CAMPO MONITOREO ANALIZADORES AUTOMÁTICOS
A7: PROYECTO: | B7: {='Dia 1'!B7:B7} -> Aerocivil | D7: MUNICIPIO: | E7: {='Dia 1'!E7:E7} -> Bogotá
A8: ESTACION DE MUESTREO: | B8: {='Dia 1'!B8:B8} -> CA1 Engativa | D8: DEPARTAMENTO: | E8: {='Dia 1'!E8:E8} -> Distrito Capital
A9: COORDENADA NORTE: | B9: {='Dia 1'!B9:B9} -> 2077821.7 | D9: COORDENADA OESTE: | E9: {='Dia 1'!E9:E9} -> 4874451.2
A10: RESPONSABLE DEL MUESTREO | B10: {='Dia 1'!B10:B10} -> Leonardo Pérez | D10: ALTURA MSNM: | E10: {='Dia 1'!E10:E10} -> 2551
A11: FECHA INICIO: | B11: ='FOM303-32-Imprimir'!C30 -> 46042 | D11: HORA INICIO: | E11: {='Dia 1'!E11:E11} -> 0
A12: FECHA FINAL: | B12: ='FOM303-32-Imprimir'!E30 -> 46042 | D12: HORA FINAL: | E12: {='Dia 1'!E12:E12} -> 0.95833333
B15: REGISTRO DE LA TEMPERATURA DEL SHELTER HORARIA PARA DETERMINAR DS T°C
B17: PERIODO DE 24 HORAS DESDE LA HORA 0 | C17: REGISTRO DE LA TEMPERATURA DEL SHELTER DE FORMA HORARIO
B21: 0 | C21: 24.406 | D21: 24.406
B22: 1 | C22: 24.019 | D22: 24.019
B23: 2 | C23: 23.704 | D23: 23.704
B24: 3 | C24: 23.85 | D24: 23.85
B25: 4 | C25: 24.176 | D25: 24.176
B26: 5 | C26: 23.548 | D26: 23.548
B27: 6 | C27: 23.372 | D27: 23.372
B28: 7 | C28: 23.552 | D28: 23.552
B29: 8 | C29: 22.504 | D29: 22.504
B30: 9 | C30: 23.581 | D30: 23.581
B31: 10 | C31: 23.159 | D31: 23.159
B32: 11 | C32: 22.57 | D32: 22.57
... B44: 23 | C44: 23.767 | D44: 23.767
B45: 24
B46: PROMEDIO TOTAL T°C | C46: =AVERAGE(C22:C45) -> 23.42413
B47: (DESVIACIÓN ESTÁNDAR) DS T°C | C47: =_xlfn.STDEV.S(C21:C45) -> 0.49762134 | D47: <2.5
B48: VERIFICACIÓN | C48: =IF(ABS(C47)>=2.5,"NO CUMPLE CON DS T°C DEL SHELTER"," CUMPLE CON DS T°C DEL SHELTER") -> CUMPLE CON DS T°C DEL SHELTER

Sheet Dia 21
B1: K2 INGENIERÍA S.A.S | F1: Versión N.07 2024-05-27 FOM303-32
B2: FORMATO DE CAMPO MONITOREO ANALIZADORES AUTOMÁTICOS
A7: PROYECTO: | B7: {='Dia 1'!B7:B7} -> Aerocivil | D7: MUNICIPIO: | E7: {='Dia 1'!E7:E7} -> Bogotá
A8: ESTACION DE MUESTREO: | B8: {='Dia 1'!B8:B8} -> CA1 Engativa | D8: DEPARTAMENTO: | E8: {='Dia 1'!E8:E8} -> Distrito Capital
A9: COORDENADA NORTE: | B9: {='Dia 1'!B9:B9} -> 2077821.7 | D9: COORDENADA OESTE: | E9: {='Dia 1'!E9:E9} -> 4874451.2
A10: RESPONSABLE DEL MUESTREO | B10: {='Dia 1'!B10:B10} -> Leonardo Pérez | D10: ALTURA MSNM: | E10: {='Dia 1'!E10:E10} -> 2551
A11: FECHA INICIO: | B11: ='FOM303-32-Imprimir'!C31 -> 46043 | D11: HORA INICIO: | E11: {='Dia 1'!E11:E11} -> 0
A12: FECHA FINAL: | B12: ='FOM303-32-Imprimir'!E31 -> 46043 | D12: HORA FINAL: | E12: {='Dia 1'!E12:E12} -> 0.95833333
B15: REGISTRO DE LA TEMPERATURA DEL SHELTER HORARIA PARA DETERMINAR DS T°C
B17: PERIODO DE 24 HORAS DESDE LA HORA 0 | C17: REGISTRO DE LA TEMPERATURA DEL SHELTER DE FORMA HORARIO
B21: 0 | C21: 23.083 | D21: 23.083
B22: 1 | C22: 22.255 | D22: 22.255
B23: 2 | C23: 21.104 | D23: 21.104
B24: 3 | C24: 20.281 | D24: 20.281
B25: 4 | C25: 20.044 | D25: 20.044
B26: 5 | C26: 19.798 | D26: 19.798
B27: 6 | C27: 20.072 | D27: 20.072
B28: 7 | C28: 23.236 | D28: 23.236
B29: 8 | C29: 23.133 | D29: 23.133
B30: 9 | C30: 22.424 | D30: 22.424
B31: 10 | C31: 23.881 | D31: 23.881
B32: 11 | C32: 23.691 | D32: 23.691
... B44: 23 | C44: 24.059 | D44: 24.059
B45: 24
B46: PROMEDIO TOTAL T°C | C46: =AVERAGE(C22:C45) -> 22.732435
B47: (DESVIACIÓN ESTÁNDAR) DS T°C | C47: =_xlfn.STDEV.S(C21:C45) -> 1.3920643 | D47: <2.5
B48: VERIFICACIÓN | C48: =IF(ABS(C47)>=2.5,"NO CUMPLE CON DS T°C DEL SHELTER"," CUMPLE CON DS T°C DEL SHELTER") -> CUMPLE CON DS T°C DEL SHELTER

Sheet Dia 22
B1: K2 INGENIERÍA S.A.S | F1: Versión N.07 2024-05-27 FOM303-32
B2: FORMATO DE CAMPO MONITOREO ANALIZADORES AUTOMÁTICOS
A7: PROYECTO: | B7: {='Dia 1'!B7:B7} -> Aerocivil | D7: MUNICIPIO: | E7: {='Dia 1'!E7:E7} -> Bogotá
A8: ESTACION DE MUESTREO: | B8: {='Dia 1'!B8:B8} -> CA1 Engativa | D8: DEPARTAMENTO: | E8: {='Dia 1'!E8:E8} -> Distrito Capital
A9: COORDENADA NORTE: | B9: {='Dia 1'!B9:B9} -> 2077821.7 | D9: COORDENADA OESTE: | E9: {='Dia 1'!E9:E9} -> 4874451.2
A10: RESPONSABLE DEL MUESTREO | B10: {='Dia 1'!B10:B10} -> Leonardo Pérez | D10: ALTURA MSNM: | E10: {='Dia 1'!E10:E10} -> 2551
A11: FECHA INICIO: | B11: ='FOM303-32-Imprimir'!C32 -> 46044 | D11: HORA INICIO: | E11: {='Dia 1'!E11:E11} -> 0
A12: FECHA FINAL: | B12: ='FOM303-32-Imprimir'!E32 -> 46044 | D12: HORA FINAL: | E12: {='Dia 1'!E12:E12} -> 0.95833333
B15: REGISTRO DE LA TEMPERATURA DEL SHELTER HORARIA PARA DETERMINAR DS T°C
B17: PERIODO DE 24 HORAS DESDE LA HORA 0 | C17: REGISTRO DE LA TEMPERATURA DEL SHELTER DE FORMA HORARIO
B21: 0 | C21: 23.746 | D21: 23.746
B22: 1 | C22: 23.443 | D22: 23.443
B23: 2 | C23: 24.016 | D23: 24.016
B24: 3 | C24: 23.701 | D24: 23.701
B25: 4 | C25: 23.176 | D25: 23.176
B26: 5 | C26: 23.015 | D26: 23.015
B27: 6 | C27: 23.561 | D27: 23.561
B28: 7 | C28: 23.785 | D28: 23.785
B29: 8 | C29: 23.643 | D29: 23.643
B30: 9 | C30: 24.037 | D30: 24.037
B31: 10 | C31: 23.597 | D31: 23.597
B32: 11 | C32: 23.884 | D32: 23.884
... B34: 13 | C34: 23.579 | D34: 23.579
B35: 14 | C35: 24.351
B36: 15 | C36: 23.75
B37: 16 | C37: 22.818
B38: 17 | C38: 21.99
B39: 18 | C39: 21.101
B40: 19 | C40: 21.088
B41: 20 | C41: 20.966
B42: 21 | C42: 20.798
B43: 22 | C43: 20.561
B44: 23 | C44: 20.396
B45: 24
B46: PROMEDIO TOTAL T°C | C46: =AVERAGE(C22:C45) -> 22.832348
B47: (DESVIACIÓN ESTÁNDAR) DS T°C | C47: =_xlfn.STDEV.S(C21:C45) -> 1.3022455 | D47: <2.5
B48: VERIFICACIÓN | C48: =IF(ABS(C47)>=2.5,"NO CUMPLE CON DS T°C DEL SHELTER"," CUMPLE CON DS T°C DEL SHELTER") -> CUMPLE CON DS T°C DEL SHELTER

Sheet Dia 23
B1: K2 INGENIERÍA S.A.S | F1: Versión N.07 2024-05-27 FOM303-32
B2: FORMATO DE CAMPO MONITOREO ANALIZADORES AUTOMÁTICOS
A7: PROYECTO: | B7: {='Dia 1'!B7:B7} -> Aerocivil | D7: MUNICIPIO: | E7: {='Dia 1'!E7:E7} -> Bogotá
A8: ESTACION DE MUESTREO: | B8: {='Dia 1'!B8:B8} -> CA1 Engativa | D8: DEPARTAMENTO: | E8: {='Dia 1'!E8:E8} -> Distrito Capital
A9: COORDENADA NORTE: | B9: {='Dia 1'!B9:B9} -> 2077821.7 | D9: COORDENADA OESTE: | E9: {='Dia 1'!E9:E9} -> 4874451.2
A10: RESPONSABLE DEL MUESTREO | B10: {='Dia 1'!B10:B10} -> Leonardo Pérez | D10: ALTURA MSNM: | E10: {='Dia 1'!E10:E10} -> 2551
A11: FECHA INICIO: | B11: ='FOM303-32-Imprimir'!C33 -> 46045 | D11: HORA INICIO: | E11: {='Dia 1'!E11:E11} -> 0
A12: FECHA FINAL: | B12: ='FOM303-32-Imprimir'!E33 -> 46045 | D12: HORA FINAL: | E12: {='Dia 1'!E12:E12} -> 0.95833333
B15: REGISTRO DE LA TEMPERATURA DEL SHELTER HORARIA PARA DETERMINAR DS T°C
B17: PERIODO DE 24 HORAS DESDE LA HORA 0 | C17: REGISTRO DE LA TEMPERATURA DEL SHELTER DE FORMA HORARIO
B21: 0 | C21: 23.816 | D21: 23.816
B22: 1 | C22: 23.608 | D22: 23.608
B23: 2 | C23: 23.743 | D23: 23.743
B24: 3 | C24: 23.858 | D24: 23.858
B25: 4 | C25: 23.889 | D25: 23.889
B26: 5 | C26: 24.244 | D26: 24.244
B27: 6 | C27: 23.927 | D27: 23.927
B28: 7 | C28: 23.261 | D28: 23.261
B29: 8 | C29: 23.342 | D29: 23.342
B30: 9 | C30: 22.863 | D30: 22.863
B31: 10 | C31: 23.081 | D31: 23.081
B32: 11 | C32: 22.766 | D32: 22.766
... B44: 23 | C44: 23.611 | D44: 23.611
B45: 24
B46: PROMEDIO TOTAL T°C | C46: =AVERAGE(C22:C45) -> 23.501609
B47: (DESVIACIÓN ESTÁNDAR) DS T°C | C47: =_xlfn.STDEV.S(C21:C45) -> 0.36039091 | D47: <2.5
B48: VERIFICACIÓN | C48: =IF(ABS(C47)>=2.5,"NO CUMPLE CON DS T°C DEL SHELTER"," CUMPLE CON DS T°C DEL SHELTER") -> CUMPLE CON DS T°C DEL SHELTER

Sheet Dia 24
B1: K2 INGENIERÍA S.A.S | F1: Versión N.07 2024-05-27 FOM303-32
B2: FORMATO DE CAMPO MONITOREO ANALIZADORES AUTOMÁTICOS
A7: PROYECTO: | B7: {='Dia 1'!B7:B7} -> Aerocivil | D7: MUNICIPIO: | E7: {='Dia 1'!E7:E7} -> Bogotá
A8: ESTACION DE MUESTREO: | B8: {='Dia 1'!B8:B8} -> CA1 Engativa | D8: DEPARTAMENTO: | E8: {='Dia 1'!E8:E8} -> Distrito Capital
A9: COORDENADA NORTE: | B9: {='Dia 1'!B9:B9} -> 2077821.7 | D9: COORDENADA OESTE: | E9: {='Dia 1'!E9:E9} -> 4874451.2
A10: RESPONSABLE DEL MUESTREO | B10: {='Dia 1'!B10:B10} -> Leonardo Pérez | D10: ALTURA MSNM: | E10: {='Dia 1'!E10:E10} -> 2551
A11: FECHA INICIO: | B11: ='FOM303-32-Imprimir'!C34 -> 46046 | D11: HORA INICIO: | E11: {='Dia 1'!E11:E11} -> 0
A12: FECHA FINAL: | B12: ='FOM303-32-Imprimir'!E34 -> 46046 | D12: HORA FINAL: | E12: {='Dia 1'!E12:E12} -> 0.95833333
B15: REGISTRO DE LA TEMPERATURA DEL SHELTER HORARIA PARA DETERMINAR DS T°C
B17: PERIODO DE 24 HORAS DESDE LA HORA 0 | C17: REGISTRO DE LA TEMPERATURA DEL SHELTER DE FORMA HORARIO
B21: 0 | C21: 23.864 | D21: 23.864
B22: 1 | C22: 23.728 | D22: 23.728
B23: 2 | C23: 23.712 | D23: 23.712
B24: 3 | C24: 23.869 | D24: 23.869
B25: 4 | C25: 23.804 | D25: 23.804
B26: 5 | C26: 24.231 | D26: 24.231
B27: 6 | C27: 23.609 | D27: 23.609
B28: 7 | C28: 23.707 | D28: 23.707
B29: 8 | C29: 22.611 | D29: 22.611
B30: 9 | C30: 23.687 | D30: 23.687
B31: 10 | C31: 23.235 | D31: 23.235
B32: 11 | C32: 23.353 | D32: 23.353
... B44: 23 | C44: 23.435 | D44: 23.435
B45: 24
B46: PROMEDIO TOTAL T°C | C46: =AVERAGE(C22:C45) -> 23.458826
B47: (DESVIACIÓN ESTÁNDAR) DS T°C | C47: =_xlfn.STDEV.S(C21:C45) -> 0.43369609 | D47: <2.5
B48: VERIFICACIÓN | C48: =IF(ABS(C47)>=2.5,"NO CUMPLE CON DS T°C DEL SHELTER"," CUMPLE CON DS T°C DEL SHELTER") -> CUMPLE CON DS T°C DEL SHELTER

Sheet Dia 25
B1: K2 INGENIERÍA S.A.S | F1: Versión N.07 2024-05-27 FOM303-32
B2: FORMATO DE CAMPO MONITOREO ANALIZADORES AUTOMÁTICOS
A7: PROYECTO: | B7: {='Dia 1'!B7:B7} -> Aerocivil | D7: MUNICIPIO: | E7: {='Dia 1'!E7:E7} -> Bogotá
A8: ESTACION DE MUESTREO: | B8: {='Dia 1'!B8:B8} -> CA1 Engativa | D8: DEPARTAMENTO: | E8: {='Dia 1'!E8:E8} -> Distrito Capital
A9: COORDENADA NORTE: | B9: {='Dia 1'!B9:B9} -> 2077821.7 | D9: COORDENADA OESTE: | E9: {='Dia 1'!E9:E9} -> 4874451.2
A10: RESPONSABLE DEL MUESTREO | B10: {='Dia 1'!B10:B10} -> Leonardo Pérez | D10: ALTURA MSNM: | E10: {='Dia 1'!E10:E10} -> 2551
A11: FECHA INICIO: | B11: ='FOM303-32-Imprimir'!C35 -> 46047 | D11: HORA INICIO: | E11: {='Dia 1'!E11:E11} -> 0
A12: FECHA FINAL: | B12: ='FOM303-32-Imprimir'!E35 -> 46047 | D12: HORA FINAL: | E12: {='Dia 1'!E12:E12} -> 0.95833333
B15: REGISTRO DE LA TEMPERATURA DEL SHELTER HORARIA PARA DETERMINAR DS T°C
B17: PERIODO DE 24 HORAS DESDE LA HORA 0 | C17: REGISTRO DE LA TEMPERATURA DEL SHELTER DE FORMA HORARIO
B21: 0 | C21: 23.461 | D21: 23.461
B22: 1 | C22: 23.372 | D22: 23.372
B23: 2 | C23: 23.322 | D23: 23.322
B24: 3 | C24: 23.361 | D24: 23.361
B25: 4 | C25: 23.326 | D25: 23.326
B26: 5 | C26: 23.868 | D26: 23.868
B27: 6 | C27: 23.692 | D27: 23.692
B28: 7 | C28: 23.474 | D28: 23.474
B29: 8 | C29: 22.455 | D29: 22.455
B30: 9 | C30: 22.433 | D30: 22.433
B31: 10 | C31: 22.956 | D31: 22.956
B32: 11 | C32: 23.159 | D32: 23.159
... B44: 23 | C44: 23.799 | D44: 23.799
B45: 24
B46: PROMEDIO TOTAL T°C | C46: =AVERAGE(C22:C45) -> 23.446522
B47: (DESVIACIÓN ESTÁNDAR) DS T°C | C47: =_xlfn.STDEV.S(C21:C45) -> 0.4500607 | D47: <2.5
B48: VERIFICACIÓN | C48: =IF(ABS(C47)>=2.5,"NO CUMPLE CON DS T°C DEL SHELTER"," CUMPLE CON DS T°C DEL SHELTER") -> CUMPLE CON DS T°C DEL SHELTER

Sheet Dia 26
B1: K2 INGENIERÍA S.A.S | F1: Versión N.07 2024-05-27 FOM303-32
B2: FORMATO DE CAMPO MONITOREO ANALIZADORES AUTOMÁTICOS
A7: PROYECTO: | B7: {='Dia 1'!B7:B7} -> Aerocivil | D7: MUNICIPIO: | E7: {='Dia 1'!E7:E7} -> Bogotá
A8: ESTACION DE MUESTREO: | B8: {='Dia 1'!B8:B8} -> CA1 Engativa | D8: DEPARTAMENTO: | E8: {='Dia 1'!E8:E8} -> Distrito Capital
A9: COORDENADA NORTE: | B9: {='Dia 1'!B9:B9} -> 2077821.7 | D9: COORDENADA OESTE: | E9: {='Dia 1'!E9:E9} -> 4874451.2
A10: RESPONSABLE DEL MUESTREO | B10: {='Dia 1'!B10:B10} -> Leonardo Pérez | D10: ALTURA MSNM: | E10: {='Dia 1'!E10:E10} -> 2551
A11: FECHA INICIO: | B11: ='FOM303-32-Imprimir'!C36 -> 46048 | D11: HORA INICIO: | E11: {='Dia 1'!E11:E11} -> 0
A12: FECHA FINAL: | B12: ='FOM303-32-Imprimir'!E36 -> 46048 | D12: HORA FINAL: | E12: {='Dia 1'!E12:E12} -> 0.95833333
B15: REGISTRO DE LA TEMPERATURA DEL SHELTER HORARIA PARA DETERMINAR DS T°C
B17: PERIODO DE 24 HORAS DESDE LA HORA 0 | C17: REGISTRO DE LA TEMPERATURA DEL SHELTER DE FORMA HORARIO
B21: 0 | C21: 23.708 | D21: 23.708
B22: 1 | C22: 23.776 | D22: 23.776
B23: 2 | C23: 23.939 | D23: 23.939
B24: 3 | C24: 23.935 | D24: 23.935
B25: 4 | C25: 23.813 | D25: 23.813
B26: 5 | C26: 23.92 | D26: 23.92
B27: 6 | C27: 23.946 | D27: 23.946
B28: 7 | C28: 23.835 | D28: 23.835
B29: 8 | C29: 23.191 | D29: 23.191
B30: 9 | C30: 23.47 | D30: 23.47
B31: 10 | C31: 23.83 | D31: 23.83
B32: 11 | C32: 23.715 | D32: 23.715
... B44: 23 | C44: 23.747 | D44: 23.747
B45: 24
B46: PROMEDIO TOTAL T°C | C46: =AVERAGE(C22:C45) -> 23.648696
B47: (DESVIACIÓN ESTÁNDAR) DS T°C | C47: =_xlfn.STDEV.S(C21:C45) -> 0.29329399 | D47: <2.5
B48: VERIFICACIÓN | C48: =IF(ABS(C47)>=2.5,"NO CUMPLE CON DS T°C DEL SHELTER"," CUMPLE CON DS T°C DEL SHELTER") -> CUMPLE CON DS T°C DEL SHELTER

Sheet Dia 27
B1: K2 INGENIERÍA S.A.S | F1: Versión N.07 2024-05-27 FOM303-32
B2: FORMATO DE CAMPO MONITOREO ANALIZADORES AUTOMÁTICOS
A7: PROYECTO: | B7: {='Dia 1'!B7:B7} -> Aerocivil | D7: MUNICIPIO: | E7: {='Dia 1'!E7:E7} -> Bogotá
A8: ESTACION DE MUESTREO: | B8: {='Dia 1'!B8:B8} -> CA1 Engativa | D8: DEPARTAMENTO: | E8: {='Dia 1'!E8:E8} -> Distrito Capital
A9: COORDENADA NORTE: | B9: {='Dia 1'!B9:B9} -> 2077821.7 | D9: COORDENADA OESTE: | E9: {='Dia 1'!E9:E9} -> 4874451.2
A10: RESPONSABLE DEL MUESTREO | B10: {='Dia 1'!B10:B10} -> Leonardo Pérez | D10: ALTURA MSNM: | E10: {='Dia 1'!E10:E10} -> 2551
A11: FECHA INICIO: | B11: ='FOM303-32-Imprimir'!C37 -> 46049 | D11: HORA INICIO: | E11: {='Dia 1'!E11:E11} -> 0
A12: FECHA FINAL: | B12: ='FOM303-32-Imprimir'!E37 -> 46049 | D12: HORA FINAL: | E12: {='Dia 1'!E12:E12} -> 0.95833333
B15: REGISTRO DE LA TEMPERATURA DEL SHELTER HORARIA PARA DETERMINAR DS T°C
B17: PERIODO DE 24 HORAS DESDE LA HORA 0 | C17: REGISTRO DE LA TEMPERATURA DEL SHELTER DE FORMA HORARIO
B21: 0 | C21: 23.991 | D21: 23.991
B22: 1 | C22: 24.085 | D22: 24.085
B23: 2 | C23: 24.018 | D23: 24.018
B24: 3 | C24: 24.25 | D24: 24.25
B25: 4 | C25: 24.421 | D25: 24.421
B26: 5 | C26: 24.378 | D26: 24.378
B27: 6 | C27: 24.013 | D27: 24.013
B28: 7 | C28: 23.676 | D28: 23.676
B29: 8 | C29: 23.515 | D29: 23.515
B30: 9 | C30: 23.433 | D30: 23.433
B31: 10 | C31: 23.239 | D31: 23.239
B32: 11 | C32: 23.893 | D32: 23.893
... B44: 23 | C44: 23.507 | D44: 23.507
B45: 24
B46: PROMEDIO TOTAL T°C | C46: =AVERAGE(C22:C45) -> 23.801696
B47: (DESVIACIÓN ESTÁNDAR) DS T°C | C47: =_xlfn.STDEV.S(C21:C45) -> 0.34690093 | D47: <2.5
B48: VERIFICACIÓN | C48: =IF(ABS(C47)>=2.5,"NO CUMPLE CON DS T°C DEL SHELTER"," CUMPLE CON DS T°C DEL SHELTER") -> CUMPLE CON DS T°C DEL SHELTER

Sheet Dia 28
B1: K2 INGENIERÍA S.A.S | F1: Versión N.07 2024-05-27 FOM303-32
B2: FORMATO DE CAMPO MONITOREO ANALIZADORES AUTOMÁTICOS
A7: PROYECTO: | B7: {='Dia 1'!B7:B7} -> Aerocivil | D7: MUNICIPIO: | E7: {='Dia 1'!E7:E7} -> Bogotá
A8: ESTACION DE MUESTREO: | B8: {='Dia 1'!B8:B8} -> CA1 Engativa | D8: DEPARTAMENTO: | E8: {='Dia 1'!E8:E8} -> Distrito Capital
A9: COORDENADA NORTE: | B9: {='Dia 1'!B9:B9} -> 2077821.7 | D9: COORDENADA OESTE: | E9: {='Dia 1'!E9:E9} -> 4874451.2
A10: RESPONSABLE DEL MUESTREO | B10: {='Dia 1'!B10:B10} -> Leonardo Pérez | D10: ALTURA MSNM: | E10: {='Dia 1'!E10:E10} -> 2551
A11: FECHA INICIO: | B11: ='FOM303-32-Imprimir'!C38 -> 46050 | D11: HORA INICIO: | E11: {='Dia 1'!E11:E11} -> 0
A12: FECHA FINAL: | B12: ='FOM303-32-Imprimir'!E38 -> 46050 | D12: HORA FINAL: | E12: {='Dia 1'!E12:E12} -> 0.95833333
B15: REGISTRO DE LA TEMPERATURA DEL SHELTER HORARIA PARA DETERMINAR DS T°C
B17: PERIODO DE 24 HORAS DESDE LA HORA 0 | C17: REGISTRO DE LA TEMPERATURA DEL SHELTER DE FORMA HORARIO
B21: 0 | C21: 23.783 | D21: 23.783
B22: 1 | C22: 23.216 | D22: 23.216
B23: 2 | C23: 22.463 | D23: 22.463
B24: 3 | C24: 21.866 | D24: 21.866
B25: 4 | C25: 21.738 | D25: 21.738
B26: 5 | C26: 22.276 | D26: 22.276
B27: 6 | C27: 22.433 | D27: 22.433
B28: 7 | C28: 23.479 | D28: 23.479
B29: 8 | C29: 23.606 | D29: 23.606
B30: 9 | C30: 23.513 | D30: 23.513
B31: 10 | C31: 23.166 | D31: 23.166
B32: 11 | C32: 23.772 | D32: 23.772
... B44: 23 | C44: 23.979 | D44: 23.979
B45: 24
B46: PROMEDIO TOTAL T°C | C46: =AVERAGE(C22:C45) -> 23.319652
B47: (DESVIACIÓN ESTÁNDAR) DS T°C | C47: =_xlfn.STDEV.S(C21:C45) -> 0.66660767 | D47: <2.5
B48: VERIFICACIÓN | C48: =IF(ABS(C47)>=2.5,"NO CUMPLE CON DS T°C DEL SHELTER"," CUMPLE CON DS T°C DEL SHELTER") -> CUMPLE CON DS T°C DEL SHELTER

Sheet Dia 29
B1: K2 INGENIERÍA S.A.S | F1: Versión N.07 2024-05-27 FOM303-32
B2: FORMATO DE CAMPO MONITOREO ANALIZADORES AUTOMÁTICOS
A7: PROYECTO: | B7: {='Dia 1'!B7:B7} -> Aerocivil | D7: MUNICIPIO: | E7: {='Dia 1'!E7:E7} -> Bogotá
A8: ESTACION DE MUESTREO: | B8: {='Dia 1'!B8:B8} -> CA1 Engativa | D8: DEPARTAMENTO: | E8: {='Dia 1'!E8:E8} -> Distrito Capital
A9: COORDENADA NORTE: | B9: {='Dia 1'!B9:B9} -> 2077821.7 | D9: COORDENADA OESTE: | E9: {='Dia 1'!E9:E9} -> 4874451.2
A10: RESPONSABLE DEL MUESTREO | B10: {='Dia 1'!B10:B10} -> Leonardo Pérez | D10: ALTURA MSNM: | E10: {='Dia 1'!E10:E10} -> 2551
A11: FECHA INICIO: | B11: ='FOM303-32-Imprimir'!C39 -> 46051 | D11: HORA INICIO: | E11: {='Dia 1'!E11:E11} -> 0
A12: FECHA FINAL: | B12: ='FOM303-32-Imprimir'!E39 -> 46051 | D12: HORA FINAL: | E12: {='Dia 1'!E12:E12} -> 0.95833333
B15: REGISTRO DE LA TEMPERATURA DEL SHELTER HORARIA PARA DETERMINAR DS T°C
B17: PERIODO DE 24 HORAS DESDE LA HORA 0 | C17: REGISTRO DE LA TEMPERATURA DEL SHELTER DE FORMA HORARIO
B21: 0 | C21: 23.459 | D21: 23.459
B22: 1 | C22: 23.506 | D22: 23.506
B23: 2 | C23: 23.404 | D23: 23.404
B24: 3 | C24: 22.77 | D24: 22.77
B25: 4 | C25: 22.614 | D25: 22.614
B26: 5 | C26: 22.37 | D26: 22.37
B27: 6 | C27: 22.696 | D27: 22.696
B28: 7 | C28: 23.822 | D28: 23.822
B29: 8 | C29: 23.583 | D29: 23.583
B30: 9 | C30: 23.152 | D30: 23.152
B31: 10 | C31: 23.957 | D31: 23.957
B32: 11 | C32: 23.213 | D32: 23.213
... B44: 23 | C44: 23.761 | D44: 23.761
B45: 24
B46: PROMEDIO TOTAL T°C | C46: =AVERAGE(C22:C45) -> 23.388565
B47: (DESVIACIÓN ESTÁNDAR) DS T°C | C47: =_xlfn.STDEV.S(C21:C45) -> 0.51400195 | D47: <2.5
B48: VERIFICACIÓN | C48: =IF(ABS(C47)>=2.5,"NO CUMPLE CON DS T°C DEL SHELTER"," CUMPLE CON DS T°C DEL SHELTER") -> CUMPLE CON DS T°C DEL SHELTER

Sheet Dia 30
B1: K2 INGENIERÍA S.A.S | F1: Versión N.07 2024-05-27 FOM303-32
B2: FORMATO DE CAMPO MONITOREO ANALIZADORES AUTOMÁTICOS
A7: PROYECTO: | B7: {='Dia 1'!B7:B7} -> Aerocivil | D7: MUNICIPIO: | E7: {='Dia 1'!E7:E7} -> Bogotá
A8: ESTACION DE MUESTREO: | B8: {='Dia 1'!B8:B8} -> CA1 Engativa | D8: DEPARTAMENTO: | E8: {='Dia 1'!E8:E8} -> Distrito Capital
A9: COORDENADA NORTE: | B9: {='Dia 1'!B9:B9} -> 2077821.7 | D9: COORDENADA OESTE: | E9: {='Dia 1'!E9:E9} -> 4874451.2
A10: RESPONSABLE DEL MUESTREO | B10: {='Dia 1'!B10:B10} -> Leonardo Pérez | D10: ALTURA MSNM: | E10: {='Dia 1'!E10:E10} -> 2551
A11: FECHA INICIO: | B11: ='FOM303-32-Imprimir'!C40 -> 46052 | D11: HORA INICIO: | E11: {='Dia 1'!E11:E11} -> 0
A12: FECHA FINAL: | B12: ='FOM303-32-Imprimir'!E40 -> 46052 | D12: HORA FINAL: | E12: {='Dia 1'!E12:E12} -> 0.95833333
B15: REGISTRO DE LA TEMPERATURA DEL SHELTER HORARIA PARA DETERMINAR DS T°C
B17: PERIODO DE 24 HORAS DESDE LA HORA 0 | C17: REGISTRO DE LA TEMPERATURA DEL SHELTER DE FORMA HORARIO
B21: 0 | C21: 23.598 | D21: 23.598
B22: 1 | C22: 23.885 | D22: 23.885
B23: 2 | C23: 24.267 | D23: 24.267
B24: 3 | C24: 23.913 | D24: 23.913
B25: 4 | C25: 23.348 | D25: 23.348
B26: 5 | C26: 23.335 | D26: 23.335
B27: 6 | C27: 23.737 | D27: 23.737
B28: 7 | C28: 23.859 | D28: 23.859
B29: 8 | C29: 23.385 | D29: 23.385
B30: 9 | C30: 23.808 | D30: 23.808
B31: 10 | C31: 23.809 | D31: 23.809
B32: 11 | C32: 23.122 | D32: 23.122
... B44: 23 | C44: 22.287 | D44: 22.287
B45: 24
B46: PROMEDIO TOTAL T°C | C46: =AVERAGE(C22:C45) -> 23.54387
B47: (DESVIACIÓN ESTÁNDAR) DS T°C | C47: =_xlfn.STDEV.S(C21:C45) -> 0.45795418 | D47: <2.5
B48: VERIFICACIÓN | C48: =IF(ABS(C47)>=2.5,"NO CUMPLE CON DS T°C DEL SHELTER"," CUMPLE CON DS T°C DEL SHELTER") -> CUMPLE CON DS T°C DEL SHELTER

Sheet Dia 31
B1: K2 INGENIERÍA S.A.S | F1: Versión N.07 2024-05-27 FOM303-32
B2: FORMATO DE CAMPO MONITOREO ANALIZADORES AUTOMÁTICOS
A7: PROYECTO: | B7: {='Dia 1'!B7:B7} -> Aerocivil | D7: MUNICIPIO: | E7: {='Dia 1'!E7:E7} -> Bogotá
A8: ESTACION DE MUESTREO: | B8: {='Dia 1'!B8:B8} -> CA1 Engativa | D8: DEPARTAMENTO: | E8: {='Dia 1'!E8:E8} -> Distrito Capital
A9: COORDENADA NORTE: | B9: {='Dia 1'!B9:B9} -> 2077821.7 | D9: COORDENADA OESTE: | E9: {='Dia 1'!E9:E9} -> 4874451.2
A10: RESPONSABLE DEL MUESTREO | B10: {='Dia 1'!B10:B10} -> Leonardo Pérez | D10: ALTURA MSNM: | E10: {='Dia 1'!E10:E10} -> 2551
A11: FECHA INICIO: | B11: ='FOM303-32-Imprimir'!C41 -> 46053 | D11: HORA INICIO: | E11: {='Dia 1'!E11:E11} -> 0
A12: FECHA FINAL: | B12: ='FOM303-32-Imprimir'!E41 -> 46053 | D12: HORA FINAL: | E12: {='Dia 1'!E12:E12} -> 0.95833333
B15: REGISTRO DE LA TEMPERATURA DEL SHELTER HORARIA PARA DETERMINAR DS T°C
B17: PERIODO DE 24 HORAS DESDE LA HORA 0 | C17: REGISTRO DE LA TEMPERATURA DEL SHELTER DE FORMA HORARIO
B21: 0 | C21: 23.522 | D21: 23.522
B22: 1 | C22: 22.617 | D22: 22.617
B23: 2 | C23: 21.735 | D23: 21.735
B24: 3 | C24: 21.22 | D24: 21.22
B25: 4 | C25: 21.187 | D25: 21.187
B26: 5 | C26: 21.102 | D26: 21.102
B27: 6 | C27: 22.548 | D27: 22.548
B28: 7 | C28: 23.942 | D28: 23.942
B29: 8 | C29: 23.919 | D29: 23.919
B30: 9 | C30: 23.7 | D30: 23.7
B31: 10 | C31: 23.862 | D31: 23.862
B32: 11 | C32: 23.812 | D32: 23.812
... B44: 23 | C44: 23.981 | D44: 23.981
B45: 24
B46: PROMEDIO TOTAL T°C | C46: =AVERAGE(C22:C45) -> 23.306565
B47: (DESVIACIÓN ESTÁNDAR) DS T°C | C47: =_xlfn.STDEV.S(C21:C45) -> 0.99270517 | D47: <2.5
